<?xml version='1.0' encoding='utf-8'?>
<robot name="hexapod_detailed">

  <!-- COLOURS -->
  <material name="body">
    <color rgba="0.7 0.7 0.7 1" />
  </material>
  <material name="coxa">
    <color rgba="0.7 0.7 0.7 1" />
  </material>
  <material name="femur">
    <color rgba="0.7 0.7 0.7 1" />
  </material>
  <material name="tibia">
    <color rgba="0.7 0.7 0.7 1" />
  </material>

  <!-- BASE LINK -->
  <link name="base_link">
    <inertial>
      <origin rpy="0 0 0" xyz="0 0 -6.800E-4" />
      <mass value="1.320" />
      <inertia ixx="5.25450858E-3" ixy="0" ixz="-1.0E-11" iyy="5.25450858E-3" iyz="-1.3E-10" izz="1.014754381E-2" />
    </inertial>
    <visual>
      <origin rpy="0 0 0" xyz="0 0 0" />
      <geometry>
        <mesh filename="package://urdf/meshes/detailed/base_mesh.STL" />
      </geometry>
      <material name="body" />
    </visual>
    <collision>
      <origin rpy="0 0 0" xyz="0 0 0" />
      <geometry>
        <mesh filename="package://urdf/meshes/detailed/base_mesh.STL" />
      </geometry>
    </collision>
  </link>

  <link name="link_1_1">
    <inertial>
      <origin rpy="0 0 0" xyz="4.992E-2 -1.400E-4 1.457E-2" />
      <mass value="0.14645" />
      <inertia ixx="6.022825E-5" ixy="-6.480E-8" ixz="9.3057E-7" iyy="6.045029E-5" iyz="-3.6292E-7" izz="4.572503E-5" />
    </inertial>
    <visual>
      <origin rpy="0 0 0" xyz="0 0 0" />
      <geometry>
        <mesh filename="package://urdf/meshes/detailed/coxa_mesh.STL" />
      </geometry>
      <material name="coxa" />
    </visual>
    <collision>
      <origin rpy="0 0 0" xyz="0 0 0" />
      <geometry>
        <mesh filename="package://urdf/meshes/detailed/coxa_mesh.STL" />
      </geometry>
    </collision>
  </link>

  <joint name="joint_1_1" type="revolute">
    <origin rpy="0 0 0" xyz="0.12529 0 -0.014" />
    <parent link="base_link" />
    <child link="link_1_1" />
    <axis xyz="0 0 1" />
    <limit effort="3.464" lower="-1.745" upper="1.745" velocity="7.686" />
  </joint>

  <link name="link_1_2">
    <inertial>
      <origin rpy="0 0 0" xyz="5.478E-2 -3.960E-3 0" />
      <mass value="0.05752" />
      <inertia ixx="3.892883E-5" ixy="1.70637E-6" ixz="0" iyy="1.2476240E-4" iyz="0" izz="9.600355E-5" />
    </inertial>
    <visual>
      <origin rpy="0 0 0" xyz="0 0 0" />
      <geometry>
        <mesh filename="package://urdf/meshes/detailed/femur_mesh.STL" />
      </geometry>
      <material name="femur" />
    </visual>
    <collision>
      <origin rpy="0 0 0" xyz="0 0 0" />
      <geometry>
        <mesh filename="package://urdf/meshes/detailed/femur_mesh.STL" />
      </geometry>
    </collision>
  </link>

  <joint name="joint_1_2" type="revolute">
    <origin rpy="1.5707963267949 0 0" xyz="0.05317 0 0" />
    <parent link="link_1_1" />
    <child link="link_1_2" />
    <axis xyz="0 0 1" />
    <limit effort="5.194" lower="-2.618" upper="2.269" velocity="5.289" />
  </joint>

  <link name="link_1_3">
    <inertial>
      <origin rpy="0 0 0" xyz="3.309E-2 7.960E-3 -2.000E-05" />
      <mass value="0.15389" />
      <inertia ixx="3.190588E-5" ixy="1.070870E-5" ixz="-1.0337E-7" iyy="1.8900301E-4" iyz="4.968E-8" izz="1.9268424E-4" />
    </inertial>
    <visual>
      <origin rpy="0 0 0" xyz="0 0 0" />
      <geometry>
        <mesh filename="package://urdf/meshes/detailed/tibia_mesh.STL" />
      </geometry>
      <material name="tibia" />
    </visual>
    <collision>
      <origin rpy="0 0 0" xyz="0 0 0" />
      <geometry>
        <mesh filename="package://urdf/meshes/detailed/tibia_mesh.STL" />
      </geometry>
    </collision>
  </link>

  <joint name="joint_1_3" type="revolute">
    <origin rpy="0 0 0" xyz="0.10188 0 0" />
    <parent link="link_1_2" />
    <child link="link_1_3" />
    <axis xyz="0 0 1" />
    <limit effort="3.464" lower="-2.967" upper="2.269" velocity="7.686" />
  </joint>

  <link name="link_2_1">
    <inertial>
      <origin rpy="0 0 0" xyz="4.992E-2 -1.400E-4 1.457E-2" />
      <mass value="0.14645" />
      <inertia ixx="6.022825E-5" ixy="-6.480E-8" ixz="9.3057E-7" iyy="6.045029E-5" iyz="-3.6292E-7" izz="4.572503E-5" />
    </inertial>
    <visual>
      <origin rpy="0 0 0" xyz="0 0 0" />
      <geometry>
        <mesh filename="package://urdf/meshes/detailed/coxa_mesh.STL" />
      </geometry>
      <material name="coxa" />
    </visual>
    <collision>
      <origin rpy="0 0 0" xyz="0 0 0" />
      <geometry>
        <mesh filename="package://urdf/meshes/detailed/coxa_mesh.STL" />
      </geometry>
    </collision>
  </link>

  <joint name="joint_2_1" type="revolute">
    <origin rpy="0 0 1.047197551" xyz="0.062645 0.1085043228 -0.014" />
    <parent link="base_link" />
    <child link="link_2_1" />
    <axis xyz="0 0 1" />
    <limit effort="3.464" lower="-1.745" upper="1.745" velocity="7.686" />
  </joint>

  <link name="link_2_2">
    <inertial>
      <origin rpy="0 0 0" xyz="5.478E-2 -3.960E-3 0" />
      <mass value="0.05752" />
      <inertia ixx="3.892883E-5" ixy="1.70637E-6" ixz="0" iyy="1.2476240E-4" iyz="0" izz="9.600355E-5" />
    </inertial>
    <visual>
      <origin rpy="0 0 0" xyz="0 0 0" />
      <geometry>
        <mesh filename="package://urdf/meshes/detailed/femur_mesh.STL" />
      </geometry>
      <material name="femur" />
    </visual>
    <collision>
      <origin rpy="0 0 0" xyz="0 0 0" />
      <geometry>
        <mesh filename="package://urdf/meshes/detailed/femur_mesh.STL" />
      </geometry>
    </collision>
  </link>

  <joint name="joint_2_2" type="revolute">
    <origin rpy="1.5707963267949 0 0" xyz="0.05317 0 0" />
    <parent link="link_2_1" />
    <child link="link_2_2" />
    <axis xyz="0 0 1" />
    <limit effort="5.194" lower="-2.618" upper="2.269" velocity="5.289" />
  </joint>

  <link name="link_2_3">
    <inertial>
      <origin rpy="0 0 0" xyz="3.309E-2 7.960E-3 -2.000E-05" />
      <mass value="0.15389" />
      <inertia ixx="3.190588E-5" ixy="1.070870E-5" ixz="-1.0337E-7" iyy="1.8900301E-4" iyz="4.968E-8" izz="1.9268424E-4" />
    </inertial>
    <visual>
      <origin rpy="0 0 0" xyz="0 0 0" />
      <geometry>
        <mesh filename="package://urdf/meshes/detailed/tibia_mesh.STL" />
      </geometry>
      <material name="tibia" />
    </visual>
    <collision>
      <origin rpy="0 0 0" xyz="0 0 0" />
      <geometry>
        <mesh filename="package://urdf/meshes/detailed/tibia_mesh.STL" />
      </geometry>
    </collision>
  </link>

  <joint name="joint_2_3" type="revolute">
    <origin rpy="0 0 0" xyz="0.10188 0 0" />
    <parent link="link_2_2" />
    <child link="link_2_3" />
    <axis xyz="0 0 1" />
    <limit effort="3.464" lower="-2.967" upper="2.269" velocity="7.686" />
  </joint>

  <link name="link_3_1">
    <inertial>
      <origin rpy="0 0 0" xyz="4.992E-2 -1.400E-4 1.457E-2" />
      <mass value="0.14645" />
      <inertia ixx="6.022825E-5" ixy="-6.480E-8" ixz="9.3057E-7" iyy="6.045029E-5" iyz="-3.6292E-7" izz="4.572503E-5" />
    </inertial>
    <visual>
      <origin rpy="0 0 0" xyz="0 0 0" />
      <geometry>
        <mesh filename="package://urdf/meshes/detailed/coxa_mesh.STL" />
      </geometry>
      <material name="coxa" />
    </visual>
    <collision>
      <origin rpy="0 0 0" xyz="0 0 0" />
      <geometry>
        <mesh filename="package://urdf/meshes/detailed/coxa_mesh.STL" />
      </geometry>
    </collision>
  </link>

  <joint name="joint_3_1" type="revolute">
    <origin rpy="0 0 2.094395102" xyz="-0.062645 0.1085043228 -0.014" />
    <parent link="base_link" />
    <child link="link_3_1" />
    <axis xyz="0 0 1" />
    <limit effort="3.464" lower="-1.745" upper="1.745" velocity="7.686" />
  </joint>

  <link name="link_3_2">
    <inertial>
      <origin rpy="0 0 0" xyz="5.478E-2 -3.960E-3 0" />
      <mass value="0.05752" />
      <inertia ixx="3.892883E-5" ixy="1.70637E-6" ixz="0" iyy="1.2476240E-4" iyz="0" izz="9.600355E-5" />
    </inertial>
    <visual>
      <origin rpy="0 0 0" xyz="0 0 0" />
      <geometry>
        <mesh filename="package://urdf/meshes/detailed/femur_mesh.STL" />
      </geometry>
      <material name="femur" />
    </visual>
    <collision>
      <origin rpy="0 0 0" xyz="0 0 0" />
      <geometry>
        <mesh filename="package://urdf/meshes/detailed/femur_mesh.STL" />
      </geometry>
    </collision>
  </link>

  <joint name="joint_3_2" type="revolute">
    <origin rpy="1.5707963267949 0 0" xyz="0.05317 0 0" />
    <parent link="link_3_1" />
    <child link="link_3_2" />
    <axis xyz="0 0 1" />
    <limit effort="5.194" lower="-2.618" upper="2.269" velocity="5.289" />
  </joint>

  <link name="link_3_3">
    <inertial>
      <origin rpy="0 0 0" xyz="3.309E-2 7.960E-3 -2.000E-05" />
      <mass value="0.15389" />
      <inertia ixx="3.190588E-5" ixy="1.070870E-5" ixz="-1.0337E-7" iyy="1.8900301E-4" iyz="4.968E-8" izz="1.9268424E-4" />
    </inertial>
    <visual>
      <origin rpy="0 0 0" xyz="0 0 0" />
      <geometry>
        <mesh filename="package://urdf/meshes/detailed/tibia_mesh.STL" />
      </geometry>
      <material name="tibia" />
    </visual>
    <collision>
      <origin rpy="0 0 0" xyz="0 0 0" />
      <geometry>
        <mesh filename="package://urdf/meshes/detailed/tibia_mesh.STL" />
      </geometry>
    </collision>
  </link>

  <joint name="joint_3_3" type="revolute">
    <origin rpy="0 0 0" xyz="0.10188 0 0" />
    <parent link="link_3_2" />
    <child link="link_3_3" />
    <axis xyz="0 0 1" />
    <limit effort="3.464" lower="-2.967" upper="2.269" velocity="7.686" />
  </joint>

  <link name="link_4_1">
    <inertial>
      <origin rpy="0 0 0" xyz="4.992E-2 -1.400E-4 1.457E-2" />
      <mass value="0.14645" />
      <inertia ixx="6.022825E-5" ixy="-6.480E-8" ixz="9.3057E-7" iyy="6.045029E-5" iyz="-3.6292E-7" izz="4.572503E-5" />
    </inertial>
    <visual>
      <origin rpy="0 0 0" xyz="0 0 0" />
      <geometry>
        <mesh filename="package://urdf/meshes/detailed/coxa_mesh.STL" />
      </geometry>
      <material name="coxa" />
    </visual>
    <collision>
      <origin rpy="0 0 0" xyz="0 0 0" />
      <geometry>
        <mesh filename="package://urdf/meshes/detailed/coxa_mesh.STL" />
      </geometry>
    </collision>
  </link>

  <joint name="joint_4_1" type="revolute">
    <origin rpy="0 0 3.141592654" xyz="-0.12529 0 -0.014" />
    <parent link="base_link" />
    <child link="link_4_1" />
    <axis xyz="0 0 1" />
    <limit effort="3.464" lower="-1.745" upper="1.745" velocity="7.686" />
  </joint>

  <link name="link_4_2">
    <inertial>
      <origin rpy="0 0 0" xyz="5.478E-2 -3.960E-3 0" />
      <mass value="0.05752" />
      <inertia ixx="3.892883E-5" ixy="1.70637E-6" ixz="0" iyy="1.2476240E-4" iyz="0" izz="9.600355E-5" />
    </inertial>
    <visual>
      <origin rpy="0 0 0" xyz="0 0 0" />
      <geometry>
        <mesh filename="package://urdf/meshes/detailed/femur_mesh.STL" />
      </geometry>
      <material name="femur" />
    </visual>
    <collision>
      <origin rpy="0 0 0" xyz="0 0 0" />
      <geometry>
        <mesh filename="package://urdf/meshes/detailed/femur_mesh.STL" />
      </geometry>
    </collision>
  </link>

  <joint name="joint_4_2" type="revolute">
    <origin rpy="1.5707963267949 0 0" xyz="0.05317 0 0" />
    <parent link="link_4_1" />
    <child link="link_4_2" />
    <axis xyz="0 0 1" />
    <limit effort="5.194" lower="-2.618" upper="2.269" velocity="5.289" />
  </joint>

  <link name="link_4_3">
    <inertial>
      <origin rpy="0 0 0" xyz="3.309E-2 7.960E-3 -2.000E-05" />
      <mass value="0.15389" />
      <inertia ixx="3.190588E-5" ixy="1.070870E-5" ixz="-1.0337E-7" iyy="1.8900301E-4" iyz="4.968E-8" izz="1.9268424E-4" />
    </inertial>
    <visual>
      <origin rpy="0 0 0" xyz="0 0 0" />
      <geometry>
        <mesh filename="package://urdf/meshes/detailed/tibia_mesh.STL" />
      </geometry>
      <material name="tibia" />
    </visual>
    <collision>
      <origin rpy="0 0 0" xyz="0 0 0" />
      <geometry>
        <mesh filename="package://urdf/meshes/detailed/tibia_mesh.STL" />
      </geometry>
    </collision>
  </link>

  <joint name="joint_4_3" type="revolute">
    <origin rpy="0 0 0" xyz="0.10188 0 0" />
    <parent link="link_4_2" />
    <child link="link_4_3" />
    <axis xyz="0 0 1" />
    <limit effort="3.464" lower="-2.967" upper="2.269" velocity="7.686" />
  </joint>

  <link name="link_5_1">
    <inertial>
      <origin rpy="0 0 0" xyz="4.992E-2 -1.400E-4 1.457E-2" />
      <mass value="0.14645" />
      <inertia ixx="6.022825E-5" ixy="-6.480E-8" ixz="9.3057E-7" iyy="6.045029E-5" iyz="-3.6292E-7" izz="4.572503E-5" />
    </inertial>
    <visual>
      <origin rpy="0 0 0" xyz="0 0 0" />
      <geometry>
        <mesh filename="package://urdf/meshes/detailed/coxa_mesh.STL" />
      </geometry>
      <material name="coxa" />
    </visual>
    <collision>
      <origin rpy="0 0 0" xyz="0 0 0" />
      <geometry>
        <mesh filename="package://urdf/meshes/detailed/coxa_mesh.STL" />
      </geometry>
    </collision>
  </link>

  <joint name="joint_5_1" type="revolute">
    <origin rpy="0 0 -2.094395102" xyz="-0.062645 -0.1085043228 -0.014" />
    <parent link="base_link" />
    <child link="link_5_1" />
    <axis xyz="0 0 1" />
    <limit effort="3.464" lower="-1.745" upper="1.745" velocity="7.686" />
  </joint>

  <link name="link_5_2">
    <inertial>
      <origin rpy="0 0 0" xyz="5.478E-2 -3.960E-3 0" />
      <mass value="0.05752" />
      <inertia ixx="3.892883E-5" ixy="1.70637E-6" ixz="0" iyy="1.2476240E-4" iyz="0" izz="9.600355E-5" />
    </inertial>
    <visual>
      <origin rpy="0 0 0" xyz="0 0 0" />
      <geometry>
        <mesh filename="package://urdf/meshes/detailed/femur_mesh.STL" />
      </geometry>
      <material name="femur" />
    </visual>
    <collision>
      <origin rpy="0 0 0" xyz="0 0 0" />
      <geometry>
        <mesh filename="package://urdf/meshes/detailed/femur_mesh.STL" />
      </geometry>
    </collision>
  </link>

  <joint name="joint_5_2" type="revolute">
    <origin rpy="1.5707963267949 0 0" xyz="0.05317 0 0" />
    <parent link="link_5_1" />
    <child link="link_5_2" />
    <axis xyz="0 0 1" />
    <limit effort="5.194" lower="-2.618" upper="2.269" velocity="5.289" />
  </joint>

  <link name="link_5_3">
    <inertial>
      <origin rpy="0 0 0" xyz="3.309E-2 7.960E-3 -2.000E-05" />
      <mass value="0.15389" />
      <inertia ixx="3.190588E-5" ixy="1.070870E-5" ixz="-1.0337E-7" iyy="1.8900301E-4" iyz="4.968E-8" izz="1.9268424E-4" />
    </inertial>
    <visual>
      <origin rpy="0 0 0" xyz="0 0 0" />
      <geometry>
        <mesh filename="package://urdf/meshes/detailed/tibia_mesh.STL" />
      </geometry>
      <material name="tibia" />
    </visual>
    <collision>
      <origin rpy="0 0 0" xyz="0 0 0" />
      <geometry>
        <mesh filename="package://urdf/meshes/detailed/tibia_mesh.STL" />
      </geometry>
    </collision>
  </link>

  <joint name="joint_5_3" type="revolute">
    <origin rpy="0 0 0" xyz="0.10188 0 0" />
    <parent link="link_5_2" />
    <child link="link_5_3" />
    <axis xyz="0 0 1" />
    <limit effort="3.464" lower="-2.967" upper="2.269" velocity="7.686" />
  </joint>

  <link name="link_6_1">
    <inertial>
      <origin rpy="0 0 0" xyz="4.992E-2 -1.400E-4 1.457E-2" />
      <mass value="0.14645" />
      <inertia ixx="6.022825E-5" ixy="-6.480E-8" ixz="9.3057E-7" iyy="6.045029E-5" iyz="-3.6292E-7" izz="4.572503E-5" />
    </inertial>
    <visual>
      <origin rpy="0 0 0" xyz="0 0 0" />
      <geometry>
        <mesh filename="package://urdf/meshes/detailed/coxa_mesh.STL" />
      </geometry>
      <material name="coxa" />
    </visual>
    <collision>
      <origin rpy="0 0 0" xyz="0 0 0" />
      <geometry>
        <mesh filename="package://urdf/meshes/detailed/coxa_mesh.STL" />
      </geometry>
    </collision>
  </link>

  <joint name="joint_6_1" type="revolute">
    <origin rpy="0 0 -1.047197551" xyz="0.062645 -0.1085043228 -0.014" />
    <parent link="base_link" />
    <child link="link_6_1" />
    <axis xyz="0 0 1" />
    <limit effort="3.464" lower="-1.745" upper="1.745" velocity="7.686" />
  </joint>

  <link name="link_6_2">
    <inertial>
      <origin rpy="0 0 0" xyz="5.478E-2 -3.960E-3 0" />
      <mass value="0.05752" />
      <inertia ixx="3.892883E-5" ixy="1.70637E-6" ixz="0" iyy="1.2476240E-4" iyz="0" izz="9.600355E-5" />
    </inertial>
    <visual>
      <origin rpy="0 0 0" xyz="0 0 0" />
      <geometry>
        <mesh filename="package://urdf/meshes/detailed/femur_mesh.STL" />
      </geometry>
      <material name="femur" />
    </visual>
    <collision>
      <origin rpy="0 0 0" xyz="0 0 0" />
      <geometry>
        <mesh filename="package://urdf/meshes/detailed/femur_mesh.STL" />
      </geometry>
    </collision>
  </link>

  <joint name="joint_6_2" type="revolute">
    <origin rpy="1.5707963267949 0 0" xyz="0.05317 0 0" />
    <parent link="link_6_1" />
    <child link="link_6_2" />
    <axis xyz="0 0 1" />
    <limit effort="5.194" lower="-2.618" upper="2.269" velocity="5.289" />
  </joint>

  <link name="link_6_3">
    <inertial>
      <origin rpy="0 0 0" xyz="3.309E-2 7.960E-3 -2.000E-05" />
      <mass value="0.15389" />
      <inertia ixx="3.190588E-5" ixy="1.070870E-5" ixz="-1.0337E-7" iyy="1.8900301E-4" iyz="4.968E-8" izz="1.9268424E-4" />
    </inertial>
    <visual>
      <origin rpy="0 0 0" xyz="0 0 0" />
      <geometry>
        <mesh filename="package://urdf/meshes/detailed/tibia_mesh.STL" />
      </geometry>
      <material name="tibia" />
    </visual>
    <collision>
      <origin rpy="0 0 0" xyz="0 0 0" />
      <geometry>
        <mesh filename="package://urdf/meshes/detailed/tibia_mesh.STL" />
      </geometry>
    </collision>
  </link>

  <joint name="joint_6_3" type="revolute">
    <origin rpy="0 0 0" xyz="0.10188 0 0" />
    <parent link="link_6_2" />
    <child link="link_6_3" />
    <axis xyz="0 0 1" />
    <limit effort="3.464" lower="-2.967" upper="2.269" velocity="7.686" />
  </joint>

</robot>